[2024-11-28T00:39:25.300+0000] {taskinstance.py:1157} INFO - Dependencies all met for dep_context=non-requeueable deps ti=<TaskInstance: load_data_to_vertica.create_table scheduled__2024-11-27T00:00:00+00:00 [queued]>
[2024-11-28T00:39:25.311+0000] {taskinstance.py:1157} INFO - Dependencies all met for dep_context=requeueable deps ti=<TaskInstance: load_data_to_vertica.create_table scheduled__2024-11-27T00:00:00+00:00 [queued]>
[2024-11-28T00:39:25.313+0000] {taskinstance.py:1359} INFO - Starting attempt 1 of 1
[2024-11-28T00:39:25.327+0000] {taskinstance.py:1380} INFO - Executing <Task(PostgresOperator): create_table> on 2024-11-27 00:00:00+00:00
[2024-11-28T00:39:25.334+0000] {standard_task_runner.py:57} INFO - Started process 2261 to run task
[2024-11-28T00:39:25.336+0000] {standard_task_runner.py:84} INFO - Running: ['***', 'tasks', 'run', 'load_data_to_vertica', 'create_table', 'scheduled__2024-11-27T00:00:00+00:00', '--job-id', '14', '--raw', '--subdir', 'DAGS_FOLDER/vertica_load_dag.py', '--cfg-path', '/tmp/tmpvg45kewk']
[2024-11-28T00:39:25.338+0000] {standard_task_runner.py:85} INFO - Job 14: Subtask create_table
[2024-11-28T00:39:25.398+0000] {task_command.py:415} INFO - Running <TaskInstance: load_data_to_vertica.create_table scheduled__2024-11-27T00:00:00+00:00 [running]> on host c8f6c342c5cd
[2024-11-28T00:39:25.503+0000] {taskinstance.py:1660} INFO - Exporting env vars: AIRFLOW_CTX_DAG_OWNER='***' AIRFLOW_CTX_DAG_ID='load_data_to_vertica' AIRFLOW_CTX_TASK_ID='create_table' AIRFLOW_CTX_EXECUTION_DATE='2024-11-27T00:00:00+00:00' AIRFLOW_CTX_TRY_NUMBER='1' AIRFLOW_CTX_DAG_RUN_ID='scheduled__2024-11-27T00:00:00+00:00'
[2024-11-28T00:39:25.505+0000] {sql.py:274} INFO - Executing: 
        CREATE TABLE IF NOT EXISTS grade.example_table (
            id INT PRIMARY KEY,
            data VARCHAR(255)
        );
        
[2024-11-28T00:39:25.518+0000] {base.py:73} INFO - Using connection ID 'vertica_conn' for task execution.
[2024-11-28T00:39:25.534+0000] {base.py:73} INFO - Using connection ID 'vertica_conn' for task execution.
[2024-11-28T00:39:25.539+0000] {taskinstance.py:1935} ERROR - Task failed with exception
Traceback (most recent call last):
  File "/home/airflow/.local/lib/python3.8/site-packages/airflow/providers/common/sql/operators/sql.py", line 280, in execute
    output = hook.run(
  File "/home/airflow/.local/lib/python3.8/site-packages/airflow/providers/common/sql/hooks/sql.py", line 385, in run
    with closing(self.get_conn()) as conn:
  File "/home/airflow/.local/lib/python3.8/site-packages/airflow/providers/postgres/hooks/postgres.py", line 154, in get_conn
    self.conn = psycopg2.connect(**conn_args)
  File "/home/airflow/.local/lib/python3.8/site-packages/psycopg2/__init__.py", line 122, in connect
    conn = _connect(dsn, connection_factory=connection_factory, **kwasync)
psycopg2.OperationalError: connection to server at "10.164.63.200", port 5432 failed: Connection refused
	Is the server running on that host and accepting TCP/IP connections?

[2024-11-28T00:39:25.550+0000] {taskinstance.py:1398} INFO - Marking task as FAILED. dag_id=load_data_to_vertica, task_id=create_table, execution_date=20241127T000000, start_date=20241128T003925, end_date=20241128T003925
[2024-11-28T00:39:25.565+0000] {standard_task_runner.py:104} ERROR - Failed to execute job 14 for task create_table (connection to server at "10.164.63.200", port 5432 failed: Connection refused
	Is the server running on that host and accepting TCP/IP connections?
; 2261)
[2024-11-28T00:39:25.607+0000] {local_task_job_runner.py:228} INFO - Task exited with return code 1
[2024-11-28T00:39:25.640+0000] {taskinstance.py:2776} INFO - 0 downstream tasks scheduled from follow-on schedule check
