[2024-11-27T07:38:34.717+0000] {taskinstance.py:1157} INFO - Dependencies all met for dep_context=non-requeueable deps ti=<TaskInstance: load_data_to_vertica.create_table manual__2024-11-27T07:38:34.329272+00:00 [queued]>
[2024-11-27T07:38:34.719+0000] {taskinstance.py:1157} INFO - Dependencies all met for dep_context=requeueable deps ti=<TaskInstance: load_data_to_vertica.create_table manual__2024-11-27T07:38:34.329272+00:00 [queued]>
[2024-11-27T07:38:34.719+0000] {taskinstance.py:1359} INFO - Starting attempt 1 of 1
[2024-11-27T07:38:34.723+0000] {taskinstance.py:1380} INFO - Executing <Task(PostgresOperator): create_table> on 2024-11-27 07:38:34.329272+00:00
[2024-11-27T07:38:34.726+0000] {standard_task_runner.py:57} INFO - Started process 182 to run task
[2024-11-27T07:38:34.727+0000] {standard_task_runner.py:84} INFO - Running: ['***', 'tasks', 'run', 'load_data_to_vertica', 'create_table', 'manual__2024-11-27T07:38:34.329272+00:00', '--job-id', '5', '--raw', '--subdir', 'DAGS_FOLDER/vertica_load_dag.py', '--cfg-path', '/tmp/tmpqejcccf4']
[2024-11-27T07:38:34.728+0000] {standard_task_runner.py:85} INFO - Job 5: Subtask create_table
[2024-11-27T07:38:34.745+0000] {task_command.py:415} INFO - Running <TaskInstance: load_data_to_vertica.create_table manual__2024-11-27T07:38:34.329272+00:00 [running]> on host c8f6c342c5cd
[2024-11-27T07:38:34.772+0000] {taskinstance.py:1660} INFO - Exporting env vars: AIRFLOW_CTX_DAG_OWNER='***' AIRFLOW_CTX_DAG_ID='load_data_to_vertica' AIRFLOW_CTX_TASK_ID='create_table' AIRFLOW_CTX_EXECUTION_DATE='2024-11-27T07:38:34.329272+00:00' AIRFLOW_CTX_TRY_NUMBER='1' AIRFLOW_CTX_DAG_RUN_ID='manual__2024-11-27T07:38:34.329272+00:00'
[2024-11-27T07:38:34.772+0000] {sql.py:274} INFO - Executing: 
        CREATE TABLE IF NOT EXISTS example_table (
            id INT PRIMARY KEY,
            data VARCHAR(255)
        );
        
[2024-11-27T07:38:34.779+0000] {taskinstance.py:1935} ERROR - Task failed with exception
Traceback (most recent call last):
  File "/home/airflow/.local/lib/python3.8/site-packages/airflow/providers/common/sql/operators/sql.py", line 275, in execute
    hook = self.get_db_hook()
  File "/home/airflow/.local/lib/python3.8/site-packages/airflow/providers/common/sql/operators/sql.py", line 186, in get_db_hook
    return self._hook
  File "/usr/local/lib/python3.8/functools.py", line 967, in __get__
    val = self.func(instance)
  File "/home/airflow/.local/lib/python3.8/site-packages/airflow/providers/common/sql/operators/sql.py", line 148, in _hook
    conn = BaseHook.get_connection(conn_id)
  File "/home/airflow/.local/lib/python3.8/site-packages/airflow/hooks/base.py", line 72, in get_connection
    conn = Connection.get_connection_from_secrets(conn_id)
  File "/home/airflow/.local/lib/python3.8/site-packages/airflow/models/connection.py", line 477, in get_connection_from_secrets
    raise AirflowNotFoundException(f"The conn_id `{conn_id}` isn't defined")
airflow.exceptions.AirflowNotFoundException: The conn_id `vertica_conn` isn't defined
[2024-11-27T07:38:34.780+0000] {taskinstance.py:1398} INFO - Marking task as FAILED. dag_id=load_data_to_vertica, task_id=create_table, execution_date=20241127T073834, start_date=20241127T073834, end_date=20241127T073834
[2024-11-27T07:38:34.783+0000] {standard_task_runner.py:104} ERROR - Failed to execute job 5 for task create_table (The conn_id `vertica_conn` isn't defined; 182)
[2024-11-27T07:38:34.786+0000] {local_task_job_runner.py:228} INFO - Task exited with return code 1
[2024-11-27T07:38:34.794+0000] {taskinstance.py:2776} INFO - 0 downstream tasks scheduled from follow-on schedule check
