[2024-11-27T07:38:33.148+0000] {taskinstance.py:1157} INFO - Dependencies all met for dep_context=non-requeueable deps ti=<TaskInstance: load_data_to_vertica.create_table manual__2024-11-27T07:38:31.376917+00:00 [queued]>
[2024-11-27T07:38:33.154+0000] {taskinstance.py:1157} INFO - Dependencies all met for dep_context=requeueable deps ti=<TaskInstance: load_data_to_vertica.create_table manual__2024-11-27T07:38:31.376917+00:00 [queued]>
[2024-11-27T07:38:33.156+0000] {taskinstance.py:1359} INFO - Starting attempt 1 of 1
[2024-11-27T07:38:33.162+0000] {taskinstance.py:1380} INFO - Executing <Task(PostgresOperator): create_table> on 2024-11-27 07:38:31.376917+00:00
[2024-11-27T07:38:33.168+0000] {standard_task_runner.py:57} INFO - Started process 180 to run task
[2024-11-27T07:38:33.170+0000] {standard_task_runner.py:84} INFO - Running: ['***', 'tasks', 'run', 'load_data_to_vertica', 'create_table', 'manual__2024-11-27T07:38:31.376917+00:00', '--job-id', '3', '--raw', '--subdir', 'DAGS_FOLDER/vertica_load_dag.py', '--cfg-path', '/tmp/tmpb82tg0yc']
[2024-11-27T07:38:33.171+0000] {standard_task_runner.py:85} INFO - Job 3: Subtask create_table
[2024-11-27T07:38:33.201+0000] {task_command.py:415} INFO - Running <TaskInstance: load_data_to_vertica.create_table manual__2024-11-27T07:38:31.376917+00:00 [running]> on host c8f6c342c5cd
[2024-11-27T07:38:33.243+0000] {taskinstance.py:1660} INFO - Exporting env vars: AIRFLOW_CTX_DAG_OWNER='***' AIRFLOW_CTX_DAG_ID='load_data_to_vertica' AIRFLOW_CTX_TASK_ID='create_table' AIRFLOW_CTX_EXECUTION_DATE='2024-11-27T07:38:31.376917+00:00' AIRFLOW_CTX_TRY_NUMBER='1' AIRFLOW_CTX_DAG_RUN_ID='manual__2024-11-27T07:38:31.376917+00:00'
[2024-11-27T07:38:33.244+0000] {sql.py:274} INFO - Executing: 
        CREATE TABLE IF NOT EXISTS example_table (
            id INT PRIMARY KEY,
            data VARCHAR(255)
        );
        
[2024-11-27T07:38:33.253+0000] {taskinstance.py:1935} ERROR - Task failed with exception
Traceback (most recent call last):
  File "/home/airflow/.local/lib/python3.8/site-packages/airflow/providers/common/sql/operators/sql.py", line 275, in execute
    hook = self.get_db_hook()
  File "/home/airflow/.local/lib/python3.8/site-packages/airflow/providers/common/sql/operators/sql.py", line 186, in get_db_hook
    return self._hook
  File "/usr/local/lib/python3.8/functools.py", line 967, in __get__
    val = self.func(instance)
  File "/home/airflow/.local/lib/python3.8/site-packages/airflow/providers/common/sql/operators/sql.py", line 148, in _hook
    conn = BaseHook.get_connection(conn_id)
  File "/home/airflow/.local/lib/python3.8/site-packages/airflow/hooks/base.py", line 72, in get_connection
    conn = Connection.get_connection_from_secrets(conn_id)
  File "/home/airflow/.local/lib/python3.8/site-packages/airflow/models/connection.py", line 477, in get_connection_from_secrets
    raise AirflowNotFoundException(f"The conn_id `{conn_id}` isn't defined")
airflow.exceptions.AirflowNotFoundException: The conn_id `vertica_conn` isn't defined
[2024-11-27T07:38:33.255+0000] {taskinstance.py:1398} INFO - Marking task as FAILED. dag_id=load_data_to_vertica, task_id=create_table, execution_date=20241127T073831, start_date=20241127T073833, end_date=20241127T073833
[2024-11-27T07:38:33.260+0000] {standard_task_runner.py:104} ERROR - Failed to execute job 3 for task create_table (The conn_id `vertica_conn` isn't defined; 180)
[2024-11-27T07:38:33.268+0000] {local_task_job_runner.py:228} INFO - Task exited with return code 1
[2024-11-27T07:38:33.279+0000] {taskinstance.py:2776} INFO - 0 downstream tasks scheduled from follow-on schedule check
