[2024-12-06T09:03:44.110+0000] {taskinstance.py:1157} INFO - Dependencies all met for dep_context=non-requeueable deps ti=<TaskInstance: load_data_to_vertica.create_table manual__2024-12-06T09:03:42.688468+00:00 [queued]>
[2024-12-06T09:03:44.113+0000] {taskinstance.py:1157} INFO - Dependencies all met for dep_context=requeueable deps ti=<TaskInstance: load_data_to_vertica.create_table manual__2024-12-06T09:03:42.688468+00:00 [queued]>
[2024-12-06T09:03:44.113+0000] {taskinstance.py:1359} INFO - Starting attempt 1 of 1
[2024-12-06T09:03:44.117+0000] {taskinstance.py:1380} INFO - Executing <Task(PostgresOperator): create_table> on 2024-12-06 09:03:42.688468+00:00
[2024-12-06T09:03:44.119+0000] {standard_task_runner.py:57} INFO - Started process 217 to run task
[2024-12-06T09:03:44.120+0000] {standard_task_runner.py:84} INFO - Running: ['***', 'tasks', 'run', 'load_data_to_vertica', 'create_table', 'manual__2024-12-06T09:03:42.688468+00:00', '--job-id', '26', '--raw', '--subdir', 'DAGS_FOLDER/vertica_load_dag.py', '--cfg-path', '/tmp/tmpq3msfc8o']
[2024-12-06T09:03:44.121+0000] {standard_task_runner.py:85} INFO - Job 26: Subtask create_table
[2024-12-06T09:03:44.207+0000] {task_command.py:415} INFO - Running <TaskInstance: load_data_to_vertica.create_table manual__2024-12-06T09:03:42.688468+00:00 [running]> on host c8f6c342c5cd
[2024-12-06T09:03:44.249+0000] {taskinstance.py:1660} INFO - Exporting env vars: AIRFLOW_CTX_DAG_OWNER='***' AIRFLOW_CTX_DAG_ID='load_data_to_vertica' AIRFLOW_CTX_TASK_ID='create_table' AIRFLOW_CTX_EXECUTION_DATE='2024-12-06T09:03:42.688468+00:00' AIRFLOW_CTX_TRY_NUMBER='1' AIRFLOW_CTX_DAG_RUN_ID='manual__2024-12-06T09:03:42.688468+00:00'
[2024-12-06T09:03:44.250+0000] {sql.py:274} INFO - Executing: 
        CREATE TABLE IF NOT EXISTS grade.example_table (
            id INT PRIMARY KEY,
            data VARCHAR(255)
        );
        
[2024-12-06T09:03:44.257+0000] {base.py:73} INFO - Using connection ID 'vertica_conn' for task execution.
[2024-12-06T09:03:44.262+0000] {base.py:73} INFO - Using connection ID 'vertica_conn' for task execution.
[2024-12-06T09:04:54.803+0000] {local_task_job_runner.py:294} WARNING - State of this instance has been externally set to restarting. Terminating instance.
[2024-12-06T09:04:54.811+0000] {process_utils.py:131} INFO - Sending 15 to group 217. PIDs of all processes in the group: [217]
[2024-12-06T09:04:54.811+0000] {process_utils.py:86} INFO - Sending the signal 15 to group 217
[2024-12-06T09:04:59.270+0000] {taskinstance.py:1630} ERROR - Received SIGTERM. Terminating subprocesses.
[2024-12-06T09:04:59.298+0000] {taskinstance.py:1935} ERROR - Task failed with exception
Traceback (most recent call last):
  File "/home/airflow/.local/lib/python3.8/site-packages/airflow/models/taskinstance.py", line 1679, in _execute_task_with_callbacks
    result = self._execute_task(context, task_orig)
  File "/home/airflow/.local/lib/python3.8/site-packages/airflow/models/taskinstance.py", line 1742, in _execute_task
    result = execute_callable(context=context, **execute_callable_kwargs)
  File "/home/airflow/.local/lib/python3.8/site-packages/airflow/providers/common/sql/operators/sql.py", line 280, in execute
    output = hook.run(
  File "/home/airflow/.local/lib/python3.8/site-packages/airflow/providers/common/sql/hooks/sql.py", line 385, in run
    with closing(self.get_conn()) as conn:
  File "/home/airflow/.local/lib/python3.8/site-packages/airflow/providers/postgres/hooks/postgres.py", line 154, in get_conn
    self.conn = psycopg2.connect(**conn_args)
  File "/home/airflow/.local/lib/python3.8/site-packages/psycopg2/__init__.py", line 122, in connect
    conn = _connect(dsn, connection_factory=connection_factory, **kwasync)
psycopg2.OperationalError: connection to server at "10.164.63.200", port 5432 failed: Connection refused
	Is the server running on that host and accepting TCP/IP connections?


During handling of the above exception, another exception occurred:

Traceback (most recent call last):
  File "/home/airflow/.local/lib/python3.8/site-packages/airflow/models/taskinstance.py", line 1516, in _run_raw_task
    self._execute_task_with_callbacks(context, test_mode, session=session)
  File "/home/airflow/.local/lib/python3.8/site-packages/airflow/models/taskinstance.py", line 1679, in _execute_task_with_callbacks
    result = self._execute_task(context, task_orig)
  File "/home/airflow/.local/lib/python3.8/site-packages/airflow/models/taskinstance.py", line 1632, in signal_handler
    raise AirflowException("Task received SIGTERM signal")
airflow.exceptions.AirflowException: Task received SIGTERM signal
[2024-12-06T09:04:59.305+0000] {taskinstance.py:1398} INFO - Marking task as UP_FOR_RETRY. dag_id=load_data_to_vertica, task_id=create_table, execution_date=20241206T090342, start_date=20241206T090344, end_date=20241206T090459
[2024-12-06T09:04:59.314+0000] {standard_task_runner.py:104} ERROR - Failed to execute job 26 for task create_table (Task received SIGTERM signal; 217)
[2024-12-06T09:04:59.332+0000] {process_utils.py:79} INFO - Process psutil.Process(pid=217, status='terminated', exitcode=1, started='09:03:43') (217) terminated with exit code 1
